Workbook
Name apple: 'Apple (iPad, Macbook)'!$A$4:$C$417
Name apple: 'Apple (безнал)'!$A$6:$C$117
Name apple: 'Apple(iPhone, Watch)'!$B$4:$D$263
Name apple: #REF!
Name audio: #REF!
Name audio: #REF!
Name audio: #REF!
Name audio: #REF!
Name audio: #REF!
Name lego: #REF!
Name аксессуары_безнал_безндс: #REF!
Name мониторы: #REF!
Name ноутбуки: #REF!
Name ноутбуки: 'Аксессуары и гаджеты в наличии'!$A$6:$E$23
Name ноутбуки: 'МБТ Xiaomi'!$A$6:$D$105
Name ноутбуки: Ноутбуки!$A$6:$F$164
Name ноутбуки: 'Ноутбуки (2)'!$A$6:$F$174
Name ноутбуки: 'Ноутбуки (3)'!$A$6:$F$416
Name ноутбуки: 'Ноутбуки (нал)'!$A$6:$C$172
Name ноутбуки: 'Предзаказ аксессуары'!$A$6:$D$101
Name ноутбуки: 'Предзаказ аксессуары и ТВ'!$A$6:$F$3067
Name ноутбуки: 'Предзаказ аксессуары(от 150)'!$A$6:$F$2314
Name ноутбуки: #REF!
Name ноутбуки: #REF!
Name ноутбуки: #REF!
Name пред_электрон_100к: #REF!
Name пред_электрон_100к: #REF!
Name пред_электрон_100к: #REF!
Name предзаказ_электрон_100к: #REF!
Name принтеры_и_мфу: #REF!
Name сетевое_оборудование: #REF!
Name смартфоны_безнал_безндс: #REF!
Name смартфоны_безнал_ндс: 'Смартфоны(безнал с НДС)'!$A$5:$C$10
Name телевизор_безнал: #REF!
Name телевизор_безнал: #REF!
Name телевизор_безнал: #REF!
Name телевизор_безнал: #REF!
Name телевизор_безнал: #REF!
Name телевизор_безнал: #REF!
Name телевизор_безнал: #REF!
Name телевизор_безнал: #REF!
Name телевизор_безнал: #REF!
Name телевизор_безнал: #REF!
Name телевизор_безнал: #REF!
Name телевизор_безнал: #REF!
Name телевизор_безнал: #REF!
Name телевизор_безнал: #REF!
Name телевизоры_безнал: #REF!
Name телевизоры_безнал_спецпр: 'Audio, приставки, умные колонки'!$B$5:$C$456
Name телевизоры_безнал_спецпр: Dyson!$B$5:$C$189
Name телевизоры_безнал_спецпр: Garmin!$B$5:$C$112
Name телевизоры_безнал_спецпр: 'Телевизоры (безнал) Спецпред-ие'!$B$5:$E$26
Name телевизоры_безнал_спецпр: 'Телевизоры в наличии'!$B$5:$E$7
Name телевизоры_наличные: #REF!
Name телевизоры_наличные: #REF!
Name телевизоры_наличные: #REF!
Name телевизоры_наличные: #REF!
Name телевизоры_наличные: #REF!
Name умная_колонка: #REF!
Name умная_колонка: #REF!

Sheet Оглавление
A1: 8-(499)-350-76-73
A2: Товар в наличии | H2: итого | I2: =SUM(I4:I22) -> 0 | J2: =SUM(J4:J22) -> 0 | K2: =SUM(K4:K22) -> 0 | L2: =SUM(L4:L22) -> 0
A3: № | B3: Категория | C3: Склад | D3: Оплата | E3: НДС | I3: кол | J3: кол б/н | K3: сумма | L3: сумма Б/Н
A4: 1 | B4: Смартфоны и кнопочные телефоны | C4: Рубин | D4: Наличные, б/н | E4: 0.22 | I4: =Смартфоны!E4 -> 0 | J4: =Смартфоны!F4 -> 0 | K4: =Смартфоны!G4 -> 0 | L4: =Смартфоны!H4 -> 0
A5: 2 | B5: Смартфоны. Безнал | C5: Рубин | D5: б/н | E5: 0.22 | I5: ='Смартфоны(безнал с НДС)'!D3 -> 0 | K5: ='Смартфоны(безнал с НДС)'!E3 -> 0
A6: 2 | B6: Apple (iPhone, Watch, Airpods, СЗУ и провода) | C6: Рубин | D6: Наличные | E6: - | I6: ='Apple(iPhone, Watch)'!E2 -> 0 | K6: ='Apple(iPhone, Watch)'!F2 -> 0
A7: 6 | B7: Гаджеты и МБТ. Выгодно! | C7: Рубин | D7: Наличные | E7: -
A8: 3 | B8: Телевизоры Xiaomi. В наличии на складе | C8: Рябиновая | D8: б/н | E8: 0.22 | I8: ='Телевизоры в наличии'!F3 -> 0 | K8: ='Телевизоры в наличии'!G3 -> 0
A9: 4 | B9: Аксессуары и гаджеты в наличии | C9: Рябиновая | D9: Наличные, б/н | E9: 0.22 | I9: ='Аксессуары и гаджеты в наличии'!F4 -> 0 | J9: ='Аксессуары и гаджеты в наличии'!G4 -> 0 | K9: ='Аксессуары и гаджеты в наличии'!H4 -> 0 | L9: ='Аксессуары и гаджеты в наличии'!I4 -> 0
A10: 5 | B10: Уцененный товар | C10: Рубин | D10: Наличные | E10: - | I10: ='Уцененный товар'!E3 -> 0 | K10: ='Уцененный товар'!F3 -> 0
A11: Под заказ
A12: № | B12: Категория | C12: Склад | D12: Оплата | E12: НДС
A13: 6 | B13: Apple (iPad, MacBook, iMac, Apple Display, CUSTOM, Pencil, Keyboard) | C13: Рубин | D13: Наличные | E13: - | I13: ='Apple (iPad, Macbook)'!D2 -> 0 | K13: ='Apple (iPad, Macbook)'!E2 -> 0
A14: 7 | B14: Гаджеты и МБТ | C14: Рубин | D14: Наличные | E14: - | I14: ='Гаджеты и МБТ'!D2 -> 0 | K14: ='Гаджеты и МБТ'!E2 -> 0
A15: 8 | B15: Гаджеты и МБТ (от 150 тыс). | C15: Рябиновая | D15: Наличные, б/н | E15: 0.22 | I15: ='Предзаказ аксессуары'!E4 -> 0 | J15: ='Предзаказ аксессуары'!F4 -> 0 | K15: ='Предзаказ аксессуары'!G4 -> 0 | L15: ='Предзаказ аксессуары'!H4 -> 0
A16: 9 | B16: Гаджеты, МБТ, ТВ, оргтехника (от 200 тыс). | C16: Рябиновая | D16: Наличные, б/н | E16: 0.22 | I16: ='Предзаказ аксессуары и ТВ'!G4 -> 0 | J16: ='Предзаказ аксессуары и ТВ'!H4 -> 0 | K16: ='Предзаказ аксессуары и ТВ'!I4 -> 0 | L16: ='Предзаказ аксессуары и ТВ'!J4 -> 0
A17: 10 | B17: МБТ Xiaomi | C17: Рябиновая | D17: Наличные, б/н | E17: 0.22 | I17: ='МБТ Xiaomi'!E4 -> 0 | J17: ='МБТ Xiaomi'!F4 -> 0 | K17: ='МБТ Xiaomi'!G4 -> 0 | L17: ='МБТ Xiaomi'!H4 -> 0
A18: 11 | B18: Телевизоры Xiaomi | C18: Рябиновая | D18: б/н | E18: 0.22
A19: 12 | B19: Audio, приставки, колонки | C19: Рубин | D19: Наличные | E19: - | I19: ='Audio, приставки, умные колонки'!D3 -> 0 | K19: ='Audio, приставки, умные колонки'!E3 -> 0
A20: 13 | B20: Dyson. | C20: Рубин | D20: Наличные | E20: - | I20: =Dyson!D3 -> 0 | K20: =Dyson!E3 -> 0
A21: 14 | B21: GARMIN | C21: Рубин | D21: Наличные | E21: -
A22: 15 | B22: Apple. (безнал от 150 тыс.) | C22: Рубин | D22: б/н | E22: 0.22 | I22: ='Apple (безнал)'!D4 -> 0 | K22: ='Apple (безнал)'!E4 -> 0
A23: 16 | B23: Ноутбуки 1 | C23: Рубин | D23: Наличные, б/н | E23: 0.22 | I23: =Ноутбуки!G4 -> 0 | J23: =Ноутбуки!H4 -> 0 | K23: =Ноутбуки!I4 -> 0 | L23: =Ноутбуки!J4 -> 0
A24: 17 | B24: Ноутбуки 2 | C24: Рубин | D24: Наличные, б/н | E24: 0.22 | I24: ='Ноутбуки (2)'!G4 -> 0 | J24: ='Ноутбуки (2)'!H4 -> 0 | K24: ='Ноутбуки (2)'!I4 -> 0 | L24: ='Ноутбуки (2)'!J4 -> 0
A25: 18 | B25: Ноутбуки 3 | C25: Рубин | D25: Наличные, б/н | E25: 0.22 | I25: ='Ноутбуки (3)'!G4 -> 0 | J25: ='Ноутбуки (3)'!H4 -> 0 | K25: ='Ноутбуки (3)'!I4 -> 0 | L25: ='Ноутбуки (3)'!J4 -> 0
A26: 19 | B26: Ноутбуки (наличные) | C26: Рубин | D26: Наличные | E26: - | I26: ='Ноутбуки (нал)'!D4 -> 0 | K26: ='Ноутбуки (нал)'!E4 -> 0
A27: "ТрейдМи" — надёжный оптовый поставщик электроники с 10+ летним опытом. Более 10 лет мы поставляем оригинальную электронику, гаджеты и бытовую технику ведущих брендов: Xiaomi, Samsung, Apple, Honor, Huawei, Realme и многих других. Работаем по всей России, напрямую со склада в Москве. Наш приоритет — долгосрочные отношения, поэтому Вы можете быть уверены в оперативности, стабильности и прозрачных условиях работы. Хотите выгодные цены и гарантированное качество? Загрузите наш актуальный прайс:
A28: 👉 Прайс-лист ТрейдМи
A29: "ТрейдМи" – электроника с доверием! 🚀
A30: Cсылка на прайс
A31: Канал в Telegram
A32: Сайт
A33: Отзывы о нас
A34: Условия сотрудничества
A35: 1. Режим работы, адрес самовывоза.
A36: Прием заявок: пн-пт с 10 до 18 часов (МСК). Сб, вс - по согласованию с менеджером. Время работы склада: пн-пт с 10 до 19 часов, сб с 10 до 16 часов Самовывоз: г. Москва, ул.Барклая 8, БЦ "Рубин", проходная. Время самовывоза небходимо согласовать с менеджером ЗАРАНЕЕ! В противном случае возможны задержки при сборке Вашего заказа.
A37: 2. Минимальный заказ
A38: Минимальная сумма заказа: 50 000 руб. Минимальное количество позиций: от 3-х штук из категории электроника. Cкидки рассчитываются индивидуально и зависят от объема конкретного заказа
... A50: Если обнаружены внешние дефекты на смартфонах, планшетах, ноутбуках, мы в качестве компенсации предоставляем скидку, либо осуществляем возврат д/с или обмен товара на аналогичный, только если клиент предоставит видео распаковки товара. Если клиент не может предоставить видео распаковки товара, мы со своей стороны готовы погасить 50% расходов по замене бракованной детали. В течение 3 (трёх) рабочих дней с момента получения товара Покупатель может обратиться к Поставщику по вопросу комплектности и внешнего вида товара, независимо от способа его покупки (наличные д/с / б/н). Если в течение этого срока Покупатель не обратился к Поставщику с рекламацией, считается, что он принял товар надлежащего качества и комплектности. При отправке телевизоров транспортными компаниями настоятельно рекомендуем заказывать жесткую упаковку или обрешетку. В противном случае претензии по внешнему виду мы не принимаем!

Sheet Смартфоны
A1: Назад в оглавление
A2: Смартфоны наличные. Предоплата 100%
A3: Внимание! Товары Samsung могут иметь вскрытую упаковку из-за таможенного досмотра.
A4: Устройства новые, неактивированные, в полной комплектации. На работу это не влияет. Возврат и обмен невозможны — нарушение упаковки не является браком, т.к. произошло не по вине поставщика. | C4: итого | E4: =SUM(смарты_нал5[Заказ нал.]) -> 0 | F4: =SUM(смарты_нал5[Заказ Б.Н.]) -> 0 | G4: =SUM(смарты_нал5[Сумма заказа нал.]) -> 0 | H4: =SUM(смарты_нал5[Сумма заказа Б.Н.]) -> 0
A5: Код | B5: Наименование | C5: Цена | D5: Цена Б.Н. | E5: Заказ нал. | F5: Заказ Б.Н. | G5: Сумма заказа нал. | H5: Сумма заказа Б.Н. | I5: особенности заказа
A6: Электроника / Blackview | D6: =IF(смарты_нал5[[#This Row],[Цена ]]>0,смарты_нал5[[#This Row],[Цена ]]/0.87,"") | G6: =IF(смарты_нал5[[#This Row],[Цена ]]<>"",смарты_нал5[[#This Row],[Цена ]]*смарты_нал5[[#This Row],[Заказ нал.]],"") | H6: =IF(смарты_нал5[[#This Row],[Цена Б.Н.]]<>"",смарты_нал5[[#This Row],[Цена Б.Н.]]*смарты_нал5[[#This Row],[Заказ Б.Н.]],"")
A7: 17813-2 | B7: Blackview BL7000 5G 8+256GB NFC Orange RUS | C7: 18600 | D7: =IF(смарты_нал5[[#This Row],[Цена ]]>0,смарты_нал5[[#This Row],[Цена ]]/0.87,"") -> 21379.31 | G7: =IF(смарты_нал5[[#This Row],[Цена ]]<>"",смарты_нал5[[#This Row],[Цена ]]*смарты_нал5[[#This Row],[Заказ нал.]],"") -> 0 | H7: =IF(смарты_нал5[[#This Row],[Цена Б.Н.]]<>"",смарты_нал5[[#This Row],[Цена Б.Н.]]*смарты_нал5[[#This Row],[Заказ Б.Н.]],"") -> 0
A8: 17803-1 | B8: Blackview BV4800 Pro 4+128GB Black RUS | C8: 8800 | D8: =IF(смарты_нал5[[#This Row],[Цена ]]>0,смарты_нал5[[#This Row],[Цена ]]/0.87,"") -> 10114.943 | G8: =IF(смарты_нал5[[#This Row],[Цена ]]<>"",смарты_нал5[[#This Row],[Цена ]]*смарты_нал5[[#This Row],[Заказ нал.]],"") -> 0 | H8: =IF(смарты_нал5[[#This Row],[Цена Б.Н.]]<>"",смарты_нал5[[#This Row],[Цена Б.Н.]]*смарты_нал5[[#This Row],[Заказ Б.Н.]],"") -> 0
A9: 17803-2 | B9: Blackview BV4800 Pro 4+128GB Orange RUS | C9: 8800 | D9: =IF(смарты_нал5[[#This Row],[Цена ]]>0,смарты_нал5[[#This Row],[Цена ]]/0.87,"") -> 10114.943 | G9: =IF(смарты_нал5[[#This Row],[Цена ]]<>"",смарты_нал5[[#This Row],[Цена ]]*смарты_нал5[[#This Row],[Заказ нал.]],"") -> 0 | H9: =IF(смарты_нал5[[#This Row],[Цена Б.Н.]]<>"",смарты_нал5[[#This Row],[Цена Б.Н.]]*смарты_нал5[[#This Row],[Заказ Б.Н.]],"") -> 0
A10: 17816-1 | B10: Blackview Fort 1 6+256GB NFC Black RUS | C10: 13400 | D10: =IF(смарты_нал5[[#This Row],[Цена ]]>0,смарты_нал5[[#This Row],[Цена ]]/0.87,"") -> 15402.299 | G10: =IF(смарты_нал5[[#This Row],[Цена ]]<>"",смарты_нал5[[#This Row],[Цена ]]*смарты_нал5[[#This Row],[Заказ нал.]],"") -> 0 | H10: =IF(смарты_нал5[[#This Row],[Цена Б.Н.]]<>"",смарты_нал5[[#This Row],[Цена Б.Н.]]*смарты_нал5[[#This Row],[Заказ Б.Н.]],"") -> 0
A11: 17815-2 | B11: Blackview Rock 2 5G 8+256GB NFC Orange RUS | C11: 17100 | D11: =IF(смарты_нал5[[#This Row],[Цена ]]>0,смарты_нал5[[#This Row],[Цена ]]/0.87,"") -> 19655.172 | G11: =IF(смарты_нал5[[#This Row],[Цена ]]<>"",смарты_нал5[[#This Row],[Цена ]]*смарты_нал5[[#This Row],[Заказ нал.]],"") -> 0 | H11: =IF(смарты_нал5[[#This Row],[Цена Б.Н.]]<>"",смарты_нал5[[#This Row],[Цена Б.Н.]]*смарты_нал5[[#This Row],[Заказ Б.Н.]],"") -> 0
A12: Электроника / Blackview / Планшеты Blackview | D12: =IF(смарты_нал5[[#This Row],[Цена ]]>0,смарты_нал5[[#This Row],[Цена ]]/0.87,"") | G12: =IF(смарты_нал5[[#This Row],[Цена ]]<>"",смарты_нал5[[#This Row],[Цена ]]*смарты_нал5[[#This Row],[Заказ нал.]],"") | H12: =IF(смарты_нал5[[#This Row],[Цена Б.Н.]]<>"",смарты_нал5[[#This Row],[Цена Б.Н.]]*смарты_нал5[[#This Row],[Заказ Б.Н.]],"")
A13: 17912-1 | B13: Blackview Active 7 11" 8+128GB LTE Black RUS | C13: 15500 | D13: =IF(смарты_нал5[[#This Row],[Цена ]]>0,смарты_нал5[[#This Row],[Цена ]]/0.87,"") -> 17816.092 | G13: =IF(смарты_нал5[[#This Row],[Цена ]]<>"",смарты_нал5[[#This Row],[Цена ]]*смарты_нал5[[#This Row],[Заказ нал.]],"") -> 0 | H13: =IF(смарты_нал5[[#This Row],[Цена Б.Н.]]<>"",смарты_нал5[[#This Row],[Цена Б.Н.]]*смарты_нал5[[#This Row],[Заказ Б.Н.]],"") -> 0
A14: 17913-1 | B14: Blackview Active 8 Pro 10.36" 8+256GB LTE Black RUS | C14: 21600 | D14: =IF(смарты_нал5[[#This Row],[Цена ]]>0,смарты_нал5[[#This Row],[Цена ]]/0.87,"") -> 24827.586 | G14: =IF(смарты_нал5[[#This Row],[Цена ]]<>"",смарты_нал5[[#This Row],[Цена ]]*смарты_нал5[[#This Row],[Заказ нал.]],"") -> 0 | H14: =IF(смарты_нал5[[#This Row],[Цена Б.Н.]]<>"",смарты_нал5[[#This Row],[Цена Б.Н.]]*смарты_нал5[[#This Row],[Заказ Б.Н.]],"") -> 0
A15: 17905-1 | B15: Blackview MEGA 2 12" 12+256GB LTE Gray RUS | C15: 16900 | D15: =IF(смарты_нал5[[#This Row],[Цена ]]>0,смарты_нал5[[#This Row],[Цена ]]/0.87,"") -> 19425.287 | G15: =IF(смарты_нал5[[#This Row],[Цена ]]<>"",смарты_нал5[[#This Row],[Цена ]]*смарты_нал5[[#This Row],[Заказ нал.]],"") -> 0 | H15: =IF(смарты_нал5[[#This Row],[Цена Б.Н.]]<>"",смарты_нал5[[#This Row],[Цена Б.Н.]]*смарты_нал5[[#This Row],[Заказ Б.Н.]],"") -> 0
A16: Электроника / Google Pixel | D16: =IF(смарты_нал5[[#This Row],[Цена ]]>0,смарты_нал5[[#This Row],[Цена ]]/0.87,"") | G16: =IF(смарты_нал5[[#This Row],[Цена ]]<>"",смарты_нал5[[#This Row],[Цена ]]*смарты_нал5[[#This Row],[Заказ нал.]],"") | H16: =IF(смарты_нал5[[#This Row],[Цена Б.Н.]]<>"",смарты_нал5[[#This Row],[Цена Б.Н.]]*смарты_нал5[[#This Row],[Заказ Б.Н.]],"")
A17: 21017-2IN | B17: Google Pixel 10 5G 12/256GB NFC Indigo IN | C17: 51500 | D17: =IF(смарты_нал5[[#This Row],[Цена ]]>0,смарты_нал5[[#This Row],[Цена ]]/0.87,"") -> 59195.402 | G17: =IF(смарты_нал5[[#This Row],[Цена ]]<>"",смарты_нал5[[#This Row],[Цена ]]*смарты_нал5[[#This Row],[Заказ нал.]],"") -> 0 | H17: =IF(смарты_нал5[[#This Row],[Цена Б.Н.]]<>"",смарты_нал5[[#This Row],[Цена Б.Н.]]*смарты_нал5[[#This Row],[Заказ Б.Н.]],"") -> 0
A18: 21017-4IN | B18: Google Pixel 10 5G 12/256GB NFC Lemongrass IN | C18: 51500 | D18: =IF(смарты_нал5[[#This Row],[Цена ]]>0,смарты_нал5[[#This Row],[Цена ]]/0.87,"") -> 59195.402 | G18: =IF(смарты_нал5[[#This Row],[Цена ]]<>"",смарты_нал5[[#This Row],[Цена ]]*смарты_нал5[[#This Row],[Заказ нал.]],"") -> 0 | H18: =IF(смарты_нал5[[#This Row],[Цена Б.Н.]]<>"",смарты_нал5[[#This Row],[Цена Б.Н.]]*смарты_нал5[[#This Row],[Заказ Б.Н.]],"") -> 0
A19: 21017-1IN | B19: Google Pixel 10 5G 12/256GB NFC Obsidian IN | C19: 51500 | D19: =IF(смарты_нал5[[#This Row],[Цена ]]>0,смарты_нал5[[#This Row],[Цена ]]/0.87,"") -> 59195.402 | G19: =IF(смарты_нал5[[#This Row],[Цена ]]<>"",смарты_нал5[[#This Row],[Цена ]]*смарты_нал5[[#This Row],[Заказ нал.]],"") -> 0 | H19: =IF(смарты_нал5[[#This Row],[Цена Б.Н.]]<>"",смарты_нал5[[#This Row],[Цена Б.Н.]]*смарты_нал5[[#This Row],[Заказ Б.Н.]],"") -> 0
A20: 21028-2AU | B20: Google Pixel 10a 5G 8/128GB NFC Fog AU | C20: 34700 | D20: =IF(смарты_нал5[[#This Row],[Цена ]]>0,смарты_нал5[[#This Row],[Цена ]]/0.87,"") -> 39885.057 | G20: =IF(смарты_нал5[[#This Row],[Цена ]]<>"",смарты_нал5[[#This Row],[Цена ]]*смарты_нал5[[#This Row],[Заказ нал.]],"") -> 0 | H20: =IF(смарты_нал5[[#This Row],[Цена Б.Н.]]<>"",смарты_нал5[[#This Row],[Цена Б.Н.]]*смарты_нал5[[#This Row],[Заказ Б.Н.]],"") -> 0
A21: 21028-3AU | B21: Google Pixel 10a 5G 8/128GB NFC Lavander AU | C21: 34700 | D21: =IF(смарты_нал5[[#This Row],[Цена ]]>0,смарты_нал5[[#This Row],[Цена ]]/0.87,"") -> 39885.057 | G21: =IF(смарты_нал5[[#This Row],[Цена ]]<>"",смарты_нал5[[#This Row],[Цена ]]*смарты_нал5[[#This Row],[Заказ нал.]],"") -> 0 | H21: =IF(смарты_нал5[[#This Row],[Цена Б.Н.]]<>"",смарты_нал5[[#This Row],[Цена Б.Н.]]*смарты_нал5[[#This Row],[Заказ Б.Н.]],"") -> 0
A22: 21028-1AU | B22: Google Pixel 10a 5G 8/128GB NFC Obsidian AU | C22: 34700 | D22: =IF(смарты_нал5[[#This Row],[Цена ]]>0,смарты_нал5[[#This Row],[Цена ]]/0.87,"") -> 39885.057 | G22: =IF(смарты_нал5[[#This Row],[Цена ]]<>"",смарты_нал5[[#This Row],[Цена ]]*смарты_нал5[[#This Row],[Заказ нал.]],"") -> 0 | H22: =IF(смарты_нал5[[#This Row],[Цена Б.Н.]]<>"",смарты_нал5[[#This Row],[Цена Б.Н.]]*смарты_нал5[[#This Row],[Заказ Б.Н.]],"") -> 0
A23: 21011-1CA | B23: Google Pixel 9 Pro XL 5G 16GB/1TB NFC Obsidian CA | C23: 64700 | D23: =IF(смарты_нал5[[#This Row],[Цена ]]>0,смарты_нал5[[#This Row],[Цена ]]/0.87,"") -> 74367.816 | G23: =IF(смарты_нал5[[#This Row],[Цена ]]<>"",смарты_нал5[[#This Row],[Цена ]]*смарты_нал5[[#This Row],[Заказ нал.]],"") -> 0 | H23: =IF(смарты_нал5[[#This Row],[Цена Б.Н.]]<>"",смарты_нал5[[#This Row],[Цена Б.Н.]]*смарты_нал5[[#This Row],[Заказ Б.Н.]],"") -> 0
A24: 21015-1IN | B24: Google Pixel 9a 5G 8/256GB NFC Obsidian IN | C24: 31800 | D24: =IF(смарты_нал5[[#This Row],[Цена ]]>0,смарты_нал5[[#This Row],[Цена ]]/0.87,"") -> 36551.724 | G24: =IF(смарты_нал5[[#This Row],[Цена ]]<>"",смарты_нал5[[#This Row],[Цена ]]*смарты_нал5[[#This Row],[Заказ нал.]],"") -> 0 | H24: =IF(смарты_нал5[[#This Row],[Цена Б.Н.]]<>"",смарты_нал5[[#This Row],[Цена Б.Н.]]*смарты_нал5[[#This Row],[Заказ Б.Н.]],"") -> 0
A25: Электроника / Honor | D25: =IF(смарты_нал5[[#This Row],[Цена ]]>0,смарты_нал5[[#This Row],[Цена ]]/0.87,"") | G25: =IF(смарты_нал5[[#This Row],[Цена ]]<>"",смарты_нал5[[#This Row],[Цена ]]*смарты_нал5[[#This Row],[Заказ нал.]],"") | H25: =IF(смарты_нал5[[#This Row],[Цена Б.Н.]]<>"",смарты_нал5[[#This Row],[Цена Б.Н.]]*смарты_нал5[[#This Row],[Заказ Б.Н.]],"") | M25: 52
A26: 16533-3UK | B26: Honor 400 12/256GB NFC Desert Gold UK | C26: 29400 | D26: =IF(смарты_нал5[[#This Row],[Цена ]]>0,смарты_нал5[[#This Row],[Цена ]]/0.87,"") -> 33793.103 | G26: =IF(смарты_нал5[[#This Row],[Цена ]]<>"",смарты_нал5[[#This Row],[Цена ]]*смарты_нал5[[#This Row],[Заказ нал.]],"") -> 0 | H26: =IF(смарты_нал5[[#This Row],[Цена Б.Н.]]<>"",смарты_нал5[[#This Row],[Цена Б.Н.]]*смарты_нал5[[#This Row],[Заказ Б.Н.]],"") -> 0
A27: 16533-1UK | B27: Honor 400 12/256GB NFC Midnight Black UK | C27: 29400 | D27: =IF(смарты_нал5[[#This Row],[Цена ]]>0,смарты_нал5[[#This Row],[Цена ]]/0.87,"") -> 33793.103 | G27: =IF(смарты_нал5[[#This Row],[Цена ]]<>"",смарты_нал5[[#This Row],[Цена ]]*смарты_нал5[[#This Row],[Заказ нал.]],"") -> 0 | H27: =IF(смарты_нал5[[#This Row],[Цена Б.Н.]]<>"",смарты_нал5[[#This Row],[Цена Б.Н.]]*смарты_нал5[[#This Row],[Заказ Б.Н.]],"") -> 0
A28: 16534-1UK | B28: Honor 400 12/512GB NFC Midnight Black UK | C28: 31000 | D28: =IF(смарты_нал5[[#This Row],[Цена ]]>0,смарты_нал5[[#This Row],[Цена ]]/0.87,"") -> 35632.184 | G28: =IF(смарты_нал5[[#This Row],[Цена ]]<>"",смарты_нал5[[#This Row],[Цена ]]*смарты_нал5[[#This Row],[Заказ нал.]],"") -> 0 | H28: =IF(смарты_нал5[[#This Row],[Цена Б.Н.]]<>"",смарты_нал5[[#This Row],[Цена Б.Н.]]*смарты_нал5[[#This Row],[Заказ Б.Н.]],"") -> 0
A29: 16534-4UK | B29: Honor 400 12/512GB NFC Tidal Blue UK | C29: 31000 | D29: =IF(смарты_нал5[[#This Row],[Цена ]]>0,смарты_нал5[[#This Row],[Цена ]]/0.87,"") -> 35632.184 | G29: =IF(смарты_нал5[[#This Row],[Цена ]]<>"",смарты_нал5[[#This Row],[Цена ]]*смарты_нал5[[#This Row],[Заказ нал.]],"") -> 0 | H29: =IF(смарты_нал5[[#This Row],[Цена Б.Н.]]<>"",смарты_нал5[[#This Row],[Цена Б.Н.]]*смарты_нал5[[#This Row],[Заказ Б.Н.]],"") -> 0
A30: 16533-3 | B30: Honor 400 12+256GB NFC Desert Gold RUS | C30: 30100 | D30: =IF(смарты_нал5[[#This Row],[Цена ]]>0,смарты_нал5[[#This Row],[Цена ]]/0.87,"") -> 34597.701 | G30: =IF(смарты_нал5[[#This Row],[Цена ]]<>"",смарты_нал5[[#This Row],[Цена ]]*смарты_нал5[[#This Row],[Заказ нал.]],"") -> 0 | H30: =IF(смарты_нал5[[#This Row],[Цена Б.Н.]]<>"",смарты_нал5[[#This Row],[Цена Б.Н.]]*смарты_нал5[[#This Row],[Заказ Б.Н.]],"") -> 0
A31: 16533-2 | B31: Honor 400 12+256GB NFC Meteor Silver RUS | C31: 30100 | D31: =IF(смарты_нал5[[#This Row],[Цена ]]>0,смарты_нал5[[#This Row],[Цена ]]/0.87,"") -> 34597.701 | G31: =IF(смарты_нал5[[#This Row],[Цена ]]<>"",смарты_нал5[[#This Row],[Цена ]]*смарты_нал5[[#This Row],[Заказ нал.]],"") -> 0 | H31: =IF(смарты_нал5[[#This Row],[Цена Б.Н.]]<>"",смарты_нал5[[#This Row],[Цена Б.Н.]]*смарты_нал5[[#This Row],[Заказ Б.Н.]],"") -> 0 | M31: 15
A32: 16533-1 | B32: Honor 400 12+256GB NFC Midnight Black RUS | C32: 30100 | D32: =IF(смарты_нал5[[#This Row],[Цена ]]>0,смарты_нал5[[#This Row],[Цена ]]/0.87,"") -> 34597.701 | G32: =IF(смарты_нал5[[#This Row],[Цена ]]<>"",смарты_нал5[[#This Row],[Цена ]]*смарты_нал5[[#This Row],[Заказ нал.]],"") -> 0 | H32: =IF(смарты_нал5[[#This Row],[Цена Б.Н.]]<>"",смарты_нал5[[#This Row],[Цена Б.Н.]]*смарты_нал5[[#This Row],[Заказ Б.Н.]],"") -> 0
A33: 16532-3KZ | B33: Honor 400 8/256GB NFC Desert Gold KZ | C33: 27400 | D33: =IF(смарты_нал5[[#This Row],[Цена ]]>0,смарты_нал5[[#This Row],[Цена ]]/0.87,"") -> 31494.253 | G33: =IF(смарты_нал5[[#This Row],[Цена ]]<>"",смарты_нал5[[#This Row],[Цена ]]*смарты_нал5[[#This Row],[Заказ нал.]],"") -> 0 | H33: =IF(смарты_нал5[[#This Row],[Цена Б.Н.]]<>"",смарты_нал5[[#This Row],[Цена Б.Н.]]*смарты_нал5[[#This Row],[Заказ Б.Н.]],"") -> 0
A34: 16560-3EU | B34: Honor 400 8/512GB NFC (No Charger) Desert Gold EU | C34: 28000 | D34: =IF(смарты_нал5[[#This Row],[Цена ]]>0,смарты_нал5[[#This Row],[Цена ]]/0.87,"") -> 32183.908 | G34: =IF(смарты_нал5[[#This Row],[Цена ]]<>"",смарты_нал5[[#This Row],[Цена ]]*смарты_нал5[[#This Row],[Заказ нал.]],"") -> 0 | H34: =IF(смарты_нал5[[#This Row],[Цена Б.Н.]]<>"",смарты_нал5[[#This Row],[Цена Б.Н.]]*смарты_нал5[[#This Row],[Заказ Б.Н.]],"") -> 0
A35: 16560-1EU | B35: Honor 400 8/512GB NFC (No Charger) Midnight Black EU | C35: 28000 | D35: =IF(смарты_нал5[[#This Row],[Цена ]]>0,смарты_нал5[[#This Row],[Цена ]]/0.87,"") -> 32183.908 | G35: =IF(смарты_нал5[[#This Row],[Цена ]]<>"",смарты_нал5[[#This Row],[Цена ]]*смарты_нал5[[#This Row],[Заказ нал.]],"") -> 0 | H35: =IF(смарты_нал5[[#This Row],[Цена Б.Н.]]<>"",смарты_нал5[[#This Row],[Цена Б.Н.]]*смарты_нал5[[#This Row],[Заказ Б.Н.]],"") -> 0
A36: 16532-3 | B36: Honor 400 8+256GB NFC Desert Gold RUS | C36: 27700 | D36: =IF(смарты_нал5[[#This Row],[Цена ]]>0,смарты_нал5[[#This Row],[Цена ]]/0.87,"") -> 31839.08 | G36: =IF(смарты_нал5[[#This Row],[Цена ]]<>"",смарты_нал5[[#This Row],[Цена ]]*смарты_нал5[[#This Row],[Заказ нал.]],"") -> 0 | H36: =IF(смарты_нал5[[#This Row],[Цена Б.Н.]]<>"",смарты_нал5[[#This Row],[Цена Б.Н.]]*смарты_нал5[[#This Row],[Заказ Б.Н.]],"") -> 0
A37: 16532-2 | B37: Honor 400 8+256GB NFC Meteor Silver RUS | C37: 27700 | D37: =IF(смарты_нал5[[#This Row],[Цена ]]>0,смарты_нал5[[#This Row],[Цена ]]/0.87,"") -> 31839.08 | G37: =IF(смарты_нал5[[#This Row],[Цена ]]<>"",смарты_нал5[[#This Row],[Цена ]]*смарты_нал5[[#This Row],[Заказ нал.]],"") -> 0 | H37: =IF(смарты_нал5[[#This Row],[Цена Б.Н.]]<>"",смарты_нал5[[#This Row],[Цена Б.Н.]]*смарты_нал5[[#This Row],[Заказ Б.Н.]],"") -> 0 | M37: 13
A38: 16532-1 | B38: Honor 400 8+256GB NFC Midnight Black RUS | C38: 27700 | D38: =IF(смарты_нал5[[#This Row],[Цена ]]>0,смарты_нал5[[#This Row],[Цена ]]/0.87,"") -> 31839.08 | G38: =IF(смарты_нал5[[#This Row],[Цена ]]<>"",смарты_нал5[[#This Row],[Цена ]]*смарты_нал5[[#This Row],[Заказ нал.]],"") -> 0 | H38: =IF(смарты_нал5[[#This Row],[Цена Б.Н.]]<>"",смарты_нал5[[#This Row],[Цена Б.Н.]]*смарты_нал5[[#This Row],[Заказ Б.Н.]],"") -> 0
A39: 16528-3 | B39: Honor 400 Lite 5G 8+256GB NFC Marrs Green RUS | C39: 18400 | D39: =IF(смарты_нал5[[#This Row],[Цена ]]>0,смарты_нал5[[#This Row],[Цена ]]/0.87,"") -> 21149.425 | G39: =IF(смарты_нал5[[#This Row],[Цена ]]<>"",смарты_нал5[[#This Row],[Цена ]]*смарты_нал5[[#This Row],[Заказ нал.]],"") -> 0 | H39: =IF(смарты_нал5[[#This Row],[Цена Б.Н.]]<>"",смарты_нал5[[#This Row],[Цена Б.Н.]]*смарты_нал5[[#This Row],[Заказ Б.Н.]],"") -> 0
A40: 16528-1 | B40: Honor 400 Lite 5G 8+256GB NFC Velvet Black RUS | C40: 18400 | D40: =IF(смарты_нал5[[#This Row],[Цена ]]>0,смарты_нал5[[#This Row],[Цена ]]/0.87,"") -> 21149.425 | G40: =IF(смарты_нал5[[#This Row],[Цена ]]<>"",смарты_нал5[[#This Row],[Цена ]]*смарты_нал5[[#This Row],[Заказ нал.]],"") -> 0 | H40: =IF(смарты_нал5[[#This Row],[Цена Б.Н.]]<>"",смарты_нал5[[#This Row],[Цена Б.Н.]]*смарты_нал5[[#This Row],[Заказ Б.Н.]],"") -> 0
...

Sheet Смартфоны(безнал с НДС)
A1: Назад в оглавление
A2: Смартфоны (б/н с НДС 22%)
A3: Товар в наличии на складе | C3: итого | D3: =SUM(смарты_бн_бндс[Заказ]) -> 0 | E3: =SUM(смарты_бн_бндс[Сумма заказа]) -> 0
A4: Наименование | B4: Количество | C4: Цена | D4: Заказ | E4: Сумма заказа
E5: =смарты_бн_бндс[[#This Row],[Цена]]*смарты_бн_бндс[[#This Row],[Заказ]] -> 0
E6: =смарты_бн_бндс[[#This Row],[Цена]]*смарты_бн_бндс[[#This Row],[Заказ]] -> 0
E7: =смарты_бн_бндс[[#This Row],[Цена]]*смарты_бн_бндс[[#This Row],[Заказ]] -> 0
E8: =смарты_бн_бндс[[#This Row],[Цена]]*смарты_бн_бндс[[#This Row],[Заказ]] -> 0
E9: =смарты_бн_бндс[[#This Row],[Цена]]*смарты_бн_бндс[[#This Row],[Заказ]] -> 0
E10: =смарты_бн_бндс[[#This Row],[Цена]]*смарты_бн_бндс[[#This Row],[Заказ]] -> 0
E11: =смарты_бн_бндс[[#This Row],[Цена]]*смарты_бн_бндс[[#This Row],[Заказ]] -> 0
E12: =смарты_бн_бндс[[#This Row],[Цена]]*смарты_бн_бндс[[#This Row],[Заказ]] -> 0
E13: =смарты_бн_бндс[[#This Row],[Цена]]*смарты_бн_бндс[[#This Row],[Заказ]] -> 0
E14: =смарты_бн_бндс[[#This Row],[Цена]]*смарты_бн_бндс[[#This Row],[Заказ]] -> 0
E15: =смарты_бн_бндс[[#This Row],[Цена]]*смарты_бн_бндс[[#This Row],[Заказ]] -> 0
E16: =смарты_бн_бндс[[#This Row],[Цена]]*смарты_бн_бндс[[#This Row],[Заказ]] -> 0
... E50: =смарты_бн_бндс[[#This Row],[Цена]]*смарты_бн_бндс[[#This Row],[Заказ]] -> 0
A51: Итог | D51: =SUBTOTAL(109,смарты_бн_бндс[Заказ]) -> 0 | E51: =SUBTOTAL(109,смарты_бн_бндс[Сумма заказа]) -> 0

Sheet Apple(iPhone, Watch)
A1: Назад в оглавление
A2: Apple (наличные). Предоплата 100% | D2: итого | E2: =SUM(Таблица512[Заказ]) -> 0 | F2: =SUM(Таблица512[Сумма заказа]) -> 0
A3: артикул | B3: Наименование | C3: страна | D3: Цена | E3: Заказ | F3: Сумма заказа
B4: Apple iPhone 11: | F4: =Таблица512[[#This Row],[Цена]]*Таблица512[[#This Row],[Заказ]] -> 0
A5: 10270-1 | B5: Apple iPhone 11 64GB Black 1sim | C5: США | D5: 28000 | F5: =Таблица512[[#This Row],[Цена]]*Таблица512[[#This Row],[Заказ]] -> 0
B6: Apple iPhone 12: | F6: =Таблица512[[#This Row],[Цена]]*Таблица512[[#This Row],[Заказ]] -> 0
A7: 10286-2 | B7: Apple iPhone 12 64GB Black 1sim | C7: США | D7: 30500 | F7: =Таблица512[[#This Row],[Цена]]*Таблица512[[#This Row],[Заказ]] -> 0
B8: Apple iPhone 13: | F8: =Таблица512[[#This Row],[Цена]]*Таблица512[[#This Row],[Заказ]] -> 0
A9: 10298-1 | B9: Apple iPhone 13 128GB Midnight 1sim | C9: Индия | D9: 38200 | F9: =Таблица512[[#This Row],[Цена]]*Таблица512[[#This Row],[Заказ]] -> 0
A10: 10299-1 | B10: Apple iPhone 13 256GB Midnight 1sim | C10: США | D10: 45800 | F10: =Таблица512[[#This Row],[Цена]]*Таблица512[[#This Row],[Заказ]] -> 0
A11: 10299-2 | B11: Apple iPhone 13 256GB Blue 1sim | C11: США | D11: 45800 | F11: =Таблица512[[#This Row],[Цена]]*Таблица512[[#This Row],[Заказ]] -> 0
A12: 10299-4 | B12: Apple iPhone 13 256GB Pink 1sim | C12: США | D12: 46300 | F12: =Таблица512[[#This Row],[Цена]]*Таблица512[[#This Row],[Заказ]] -> 0
A13: 10300-3 | B13: Apple iPhone 13 512GB Starlight 1sim | C13: США | D13: 50300 | F13: =Таблица512[[#This Row],[Цена]]*Таблица512[[#This Row],[Заказ]] -> 0
A14: 10300-5 | B14: Apple iPhone 13 512GB Red 1sim | C14: США | D14: 49500 | F14: =Таблица512[[#This Row],[Цена]]*Таблица512[[#This Row],[Заказ]] -> 0
B15: Apple iPhone 14: | F15: =Таблица512[[#This Row],[Цена]]*Таблица512[[#This Row],[Заказ]] -> 0
A16: 10312-3 | B16: Apple iPhone 14 128GB Starlight 1sim | C16: Индия | D16: 41700 | F16: =Таблица512[[#This Row],[Цена]]*Таблица512[[#This Row],[Заказ]] -> 0
A17: 10312-2 | B17: Apple iPhone 14 128GB Blue 1sim | C17: Индия | D17: 41300 | F17: =Таблица512[[#This Row],[Цена]]*Таблица512[[#This Row],[Заказ]] -> 0
A18: 10312-4 | B18: Apple iPhone 14 128GB Purple 1sim | C18: Индия | D18: 43000 | F18: =Таблица512[[#This Row],[Цена]]*Таблица512[[#This Row],[Заказ]] -> 0
A19: 10312-6 | B19: Apple iPhone 14 128GB Yellow 1sim | C19: Индия | D19: 39000 | F19: =Таблица512[[#This Row],[Цена]]*Таблица512[[#This Row],[Заказ]] -> 0
A20: 10313-1 | B20: Apple iPhone 14 256GB Midnight 1sim | C20: Индия | D20: 44200 | F20: =Таблица512[[#This Row],[Цена]]*Таблица512[[#This Row],[Заказ]] -> 0
A21: 10313-3 | B21: Apple iPhone 14 256GB Starlight 1sim | C21: Индия | D21: 47000 | F21: =Таблица512[[#This Row],[Цена]]*Таблица512[[#This Row],[Заказ]] -> 0
A22: 10313-2 | B22: Apple iPhone 14 256GB Blue 1sim | C22: Индия | D22: 48800 | F22: =Таблица512[[#This Row],[Цена]]*Таблица512[[#This Row],[Заказ]] -> 0
B23: Apple iPhone 14 512GB Blue eSIM | C23: США | D23: 42700 | F23: =Таблица512[[#This Row],[Цена]]*Таблица512[[#This Row],[Заказ]] -> 0
B24: Apple iPhone 14 512GB Midnight eSIM | C24: США | D24: 43100 | F24: =Таблица512[[#This Row],[Цена]]*Таблица512[[#This Row],[Заказ]] -> 0
B25: Apple iPhone 14 512GB Midnight 1sim | C25: Индия | D25: 47000 | F25: =Таблица512[[#This Row],[Цена]]*Таблица512[[#This Row],[Заказ]] -> 0
A26: 10314-3 | B26: Apple iPhone 14 512GB Starlight 1sim | C26: Индия | D26: 49600 | F26: =Таблица512[[#This Row],[Цена]]*Таблица512[[#This Row],[Заказ]] -> 0
A27: 10314-2 | B27: Apple iPhone 14 512GB Blue 1sim | C27: Индия | D27: 49600 | F27: =Таблица512[[#This Row],[Цена]]*Таблица512[[#This Row],[Заказ]] -> 0
B28: Apple iPhone 14 512GB Purple 1sim | C28: Индия | D28: 49700 | F28: =Таблица512[[#This Row],[Цена]]*Таблица512[[#This Row],[Заказ]] -> 0
A29: 10314-5 | B29: Apple iPhone 14 512GB Red 1sim | C29: Индия | D29: 46800 | F29: =Таблица512[[#This Row],[Цена]]*Таблица512[[#This Row],[Заказ]] -> 0
B30: Apple iPhone 14 Plus: | F30: =Таблица512[[#This Row],[Цена]]*Таблица512[[#This Row],[Заказ]] -> 0
B31: Apple iPhone 14 Plus 128GB Yellow 2sim | C31: Гонконг | D31: 42400 | F31: =Таблица512[[#This Row],[Цена]]*Таблица512[[#This Row],[Заказ]] -> 0
A32: 10323-6 | B32: Apple iPhone 14 Plus 128GB Yellow 1sim | C32: Индия | D32: 42500 | F32: =Таблица512[[#This Row],[Цена]]*Таблица512[[#This Row],[Заказ]] -> 0
B33: Apple iPhone 14 Plus 256GB Blue eSIM | C33: США | D33: 44400 | F33: =Таблица512[[#This Row],[Цена]]*Таблица512[[#This Row],[Заказ]] -> 0
B34: Apple iPhone 14 Plus 256GB Purple eSIM | C34: США | D34: 44400 | F34: =Таблица512[[#This Row],[Цена]]*Таблица512[[#This Row],[Заказ]] -> 0
B35: Apple iPhone 14 Plus 256GB Red eSIM | C35: США | D35: 43500 | F35: =Таблица512[[#This Row],[Цена]]*Таблица512[[#This Row],[Заказ]] -> 0
B36: Apple iPhone 14 Plus 512GB Yellow eSIM | C36: США | D36: 46800 | F36: =Таблица512[[#This Row],[Цена]]*Таблица512[[#This Row],[Заказ]] -> 0
B37: Apple iPhone 14 Plus 512GB Starlight 1sim | C37: Индия | D37: 50000 | F37: =Таблица512[[#This Row],[Цена]]*Таблица512[[#This Row],[Заказ]] -> 0
B38: Apple iPhone 14 Plus 512GB Blue 1sim | C38: Индия | D38: 50300 | F38: =Таблица512[[#This Row],[Цена]]*Таблица512[[#This Row],[Заказ]] -> 0
B39: Apple iPhone 14 Plus 512GB Purple 1sim | C39: Индия | D39: 50000 | F39: =Таблица512[[#This Row],[Цена]]*Таблица512[[#This Row],[Заказ]] -> 0
B40: Apple iPhone 14 Pro Max: | F40: =Таблица512[[#This Row],[Цена]]*Таблица512[[#This Row],[Заказ]] -> 0
...

Sheet Apple (iPad, Macbook)
A1: Назад в оглавление
A2: Apple (наличные). Срок поставки на наш склад: 1 день. Предоплата 100% | C2: итого | D2: =SUM(Таблица59[Заказ]) -> 0 | E2: =SUM(Таблица59[Сумма заказа]) -> 0
A3: Наименование | B3: Особенности | C3: Цена | D3: Заказ | E3: Сумма заказа
A4: iPad Air M4 (2026) | E4: =Таблица59[[#This Row],[Цена]]*Таблица59[[#This Row],[Заказ]] -> 0
A5: Pencil USB-C | C5: 7000 | E5: =Таблица59[[#This Row],[Цена]]*Таблица59[[#This Row],[Заказ]] -> 0
A6: Apple Pencil 2 | C6: 7300 | E6: =Таблица59[[#This Row],[Цена]]*Таблица59[[#This Row],[Заказ]] -> 0
A7: Apple Pencil 2 б/у | C7: 5500 | E7: =Таблица59[[#This Row],[Цена]]*Таблица59[[#This Row],[Заказ]] -> 0
A8: Apple Pencil Pro | C8: 9500 | E8: =Таблица59[[#This Row],[Цена]]*Таблица59[[#This Row],[Заказ]] -> 0
A9: Magic Keyboard iPad Air 11 М2/M3/М4 2024 -2026 Белый (MDFV4) | C9: 30500 | E9: =Таблица59[[#This Row],[Цена]]*Таблица59[[#This Row],[Заказ]] -> 0
A10: Magic Keyboard iPad Air 11 М2/M3/М4 2024 -2026 Черный (MGYX4) | C10: 30500 | E10: =Таблица59[[#This Row],[Цена]]*Таблица59[[#This Row],[Заказ]] -> 0
A11: iPad Air 11 (M4) 2026 128 Wi-Fi Grey | B11: Гонконг, Grey | C11: 45500 | E11: =Таблица59[[#This Row],[Цена]]*Таблица59[[#This Row],[Заказ]] -> 0
A12: iPad Air 11 (M4) 2026 128 Wi-Fi Starlight | B12: Гонконг, Starlight | C12: 45000 | E12: =Таблица59[[#This Row],[Цена]]*Таблица59[[#This Row],[Заказ]] -> 0
A13: iPad Air 11 (M4) 2026 128 Wi-Fi Blue | B13: Гонконг, Blue | C13: 45000 | E13: =Таблица59[[#This Row],[Цена]]*Таблица59[[#This Row],[Заказ]] -> 0
A14: iPad Air 11 (M4) 2026 128 Wi-Fi Purple | B14: Гонконг, Purple | C14: 44500 | E14: =Таблица59[[#This Row],[Цена]]*Таблица59[[#This Row],[Заказ]] -> 0
A15: iPad Air 11 (M4) 2026 128 LTE Grey | B15: Гонконг, Grey | C15: 62900 | E15: =Таблица59[[#This Row],[Цена]]*Таблица59[[#This Row],[Заказ]] -> 0
A16: iPad Air 11 (M4) 2026 128 LTE Starlight | B16: Гонконг, Starlight | C16: 62900 | E16: =Таблица59[[#This Row],[Цена]]*Таблица59[[#This Row],[Заказ]] -> 0
A17: iPad Air 11 (M4) 2026 128 LTE Blue | B17: Гонконг, Blue | C17: 61500 | E17: =Таблица59[[#This Row],[Цена]]*Таблица59[[#This Row],[Заказ]] -> 0
A18: iPad Air 11 (M4) 2026 128 LTE Purple | B18: Гонконг, Purple | C18: 61500 | E18: =Таблица59[[#This Row],[Цена]]*Таблица59[[#This Row],[Заказ]] -> 0
A19: iPad Air 11 (M4) 2026 256 Wi-Fi Grey | B19: Гонконг, Grey | C19: 56000 | E19: =Таблица59[[#This Row],[Цена]]*Таблица59[[#This Row],[Заказ]] -> 0
A20: iPad Air 11 (M4) 2026 256 Wi-Fi Blue | B20: Гонконг, Blue | C20: 54900 | E20: =Таблица59[[#This Row],[Цена]]*Таблица59[[#This Row],[Заказ]] -> 0
A21: iPad Air 11 (M4) 2026 256 Wi-Fi Purple | B21: Гонконг, Purple | C21: 56000 | E21: =Таблица59[[#This Row],[Цена]]*Таблица59[[#This Row],[Заказ]] -> 0
A22: iPad Air 11 (M4) 2026 256 Wi-Fi Starlight | B22: Гонконг, Starlight | C22: 57000 | E22: =Таблица59[[#This Row],[Цена]]*Таблица59[[#This Row],[Заказ]] -> 0
... A66: iPad Air 13 (M4) 2026 1TB LTE Purple | B66: США, Purple | C66: 137000 | E66: =Таблица59[[#This Row],[Цена]]*Таблица59[[#This Row],[Заказ]] -> 0
A67: iPad Air M3 (2025) | E67: =Таблица59[[#This Row],[Цена]]*Таблица59[[#This Row],[Заказ]] -> 0
A68: iPad Air 11 M3 (2025) 128 LTE Gray | B68: США, Gray | C68: 59000 | E68: =Таблица59[[#This Row],[Цена]]*Таблица59[[#This Row],[Заказ]] -> 0
A69: iPad Air 11 M3 (2025) 256 LTE Grey | B69: Grey | C69: 71500 | E69: =Таблица59[[#This Row],[Цена]]*Таблица59[[#This Row],[Заказ]] -> 0
A70: iPad Air 11 M3 (2025) 256 LTE Starlight | B70: Starlight | C70: 71500 | E70: =Таблица59[[#This Row],[Цена]]*Таблица59[[#This Row],[Заказ]] -> 0
A71: iPad Air 11 M3 (2025) 256 LTE Blue | B71: Blue | C71: 71500 | E71: =Таблица59[[#This Row],[Цена]]*Таблица59[[#This Row],[Заказ]] -> 0
A72: iPad Air 13 128GB Purple M3 LTE | B72: Purple | C72: 67000 | E72: =Таблица59[[#This Row],[Цена]]*Таблица59[[#This Row],[Заказ]] -> 0
A73: iPad Air 13 128GB Starlight M3 LTE | B73: Starlight | C73: 68500 | E73: =Таблица59[[#This Row],[Цена]]*Таблица59[[#This Row],[Заказ]] -> 0
A74: iPad Air 13 128GB Blue M3 LTE | B74: Blue | C74: 67000 | E74: =Таблица59[[#This Row],[Цена]]*Таблица59[[#This Row],[Заказ]] -> 0
A75: iPad Air M2 (2024) | E75: =Таблица59[[#This Row],[Цена]]*Таблица59[[#This Row],[Заказ]] -> 0
A76: iPad Air 11 (M2) 2024 128 LTE Grey | B76: США, Grey | C76: 56000 | E76: =Таблица59[[#This Row],[Цена]]*Таблица59[[#This Row],[Заказ]] -> 0
A77: iPad Air 11 (M2) 2024 128 LTE Starlight | B77: США, Starlight | C77: 56000 | E77: =Таблица59[[#This Row],[Цена]]*Таблица59[[#This Row],[Заказ]] -> 0
A78: iPad Air 11 (M2) 2024 128 LTE Blue | B78: США, Blue | C78: 56000 | E78: =Таблица59[[#This Row],[Цена]]*Таблица59[[#This Row],[Заказ]] -> 0
A79: iPad Air 11 (M2) 2024 128 LTE Purple | B79: США, Purple | C79: 56000 | E79: =Таблица59[[#This Row],[Цена]]*Таблица59[[#This Row],[Заказ]] -> 0
A80: iPad Air 11 (M2) 2024 256 LTE Blue | B80: США, Blue | C80: 60000 | E80: =Таблица59[[#This Row],[Цена]]*Таблица59[[#This Row],[Заказ]] -> 0
A81: iPad Air 11 (M2) 2024 512 Wi-Fi Starlight | B81: Мексика, ОАЭ, Starlight | C81: 60000 | E81: =Таблица59[[#This Row],[Цена]]*Таблица59[[#This Row],[Заказ]] -> 0
A82: iPad Air 11 (M2) 2024 512 LTE Grey | B82: США, Grey | C82: 65000 | E82: =Таблица59[[#This Row],[Цена]]*Таблица59[[#This Row],[Заказ]] -> 0
A83: iPad Air 11 (M2) 2024 512 LTE Starlight | B83: США, Starlight | C83: 65000 | E83: =Таблица59[[#This Row],[Цена]]*Таблица59[[#This Row],[Заказ]] -> 0
...

Sheet Телевизоры в наличии
A1: Назад в оглавление
A2: Телевизоры (безнал с НДС 22%) Спецпредложение!
A3: В наличии на складе, предоплата 100%, от 1 штуки! | E3: итого | F3: =SUM(Таблица13[Заказ]) -> 0 | G3: =SUM(Таблица13[Сумма заказа]) -> 0
A4: Артикул | B4: Наименование | C4: доступное количество | D4: от 1шт | E4: от 20 шт | F4: Заказ | G4: Сумма заказа | H4: доп.информация
A5: 68481RUS | B5: Mi LED TV A 43 FHD 2026 (L43MB-AFRU) | C5: 10 | D5: 20800 | E5: 20500 | G5: =IF('Телевизоры в наличии'!$F5<=19,D5*F5,'Телевизоры в наличии'!$E5*F5) -> 0 | H5: промо
A6: 68473RUS | B6: Mi LED TV A Pro 50 2026 (L50MB-APRU) | C6: 2 | D6: 30000 | E6: 29500 | G6: =IF('Телевизоры в наличии'!$F6<=19,D6*F6,'Телевизоры в наличии'!$E6*F6) -> 0
A7: 68472RUS | B7: Mi LED TV A 65 2026 (L65MB-ARU) | C7: 3 | D7: 42200 | E7: 41400 | G7: =IF('Телевизоры в наличии'!$F7<=19,D7*F7,'Телевизоры в наличии'!$E7*F7) -> 0 | H7: промо
A8: Итог | F8: =SUBTOTAL(109,Таблица13[Заказ]) -> 0 | G8: =SUBTOTAL(109,Таблица13[Сумма заказа]) -> 0

Sheet Уцененный товар
A1: Назад в оглавление
A2: Уцененный товар. На объемные заказы - скидка
D3: итого | E3: =SUM(Таблица323[Заказ]) -> 0 | F3: =SUM(Таблица323[Сумма заказа]) -> 0
A4: Код | B4: Наименование | C4: Причина уценки | D4: Цена | E4: Заказ | F4: Сумма заказа
A5: Электроника / Уценка Электроника | F5: =IF(Таблица323[[#This Row],[Цена ]]>0,Таблица323[[#This Row],[Цена ]]*Таблица323[[#This Row],[Заказ]],"")
A6: 16538-1BU | B6: Honor X6c 6+128GB NFC Midnight Black RUS Уценка | C6: Надорвана коробка с тыльной стороны | D6: 7500 | F6: =IF(Таблица323[[#This Row],[Цена ]]>0,Таблица323[[#This Row],[Цена ]]*Таблица323[[#This Row],[Заказ]],"") -> 0
A7: 16540-2BU | B7: Honor X7d 6+128GB NFC Meteor Silver RUS Уценка | C7: Повреждена коробка с тыльной стороны | D7: 11000 | F7: =IF(Таблица323[[#This Row],[Цена ]]>0,Таблица323[[#This Row],[Цена ]]*Таблица323[[#This Row],[Заказ]],"") -> 0
A8: 16541-1BU | B8: Honor X7d 8+256GB NFC Velvet Black RUS Уценка | C8: Повреждена коробка с тыльной стороны | D8: 13000 | F8: =IF(Таблица323[[#This Row],[Цена ]]>0,Таблица323[[#This Row],[Цена ]]*Таблица323[[#This Row],[Заказ]],"") -> 0
A9: 16727-1BU | B9: Infinix HOT 60 Pro 8+128GB NFC Black RUS Уценка | C9: С тыльной стороны повреждена коробка | D9: 10900 | F9: =IF(Таблица323[[#This Row],[Цена ]]>0,Таблица323[[#This Row],[Цена ]]*Таблица323[[#This Row],[Заказ]],"") -> 0
A10: 282156-1BU | B10: Realme Note 70 6+128GB NFC Black RUS Уценка | C10: Коробка с тыльной стороны пробита в двух местах | D10: 6800 | F10: =IF(Таблица323[[#This Row],[Цена ]]>0,Таблица323[[#This Row],[Цена ]]*Таблица323[[#This Row],[Заказ]],"") -> 0
A11: 281326-1BU | B11: Samsung Galaxy A07 4+128GB Black RUS Уценка | C11: С тыльной стороны повреждена коробка , пломбы целые | D11: 7500 | F11: =IF(Таблица323[[#This Row],[Цена ]]>0,Таблица323[[#This Row],[Цена ]]*Таблица323[[#This Row],[Заказ]],"") -> 0
A12: 281295-1BU | B12: Samsung Galaxy A16 4+128GB Blue Black RUS Уценка | C12: надорвана коробка , пломбы целы , не вскрывался | D12: 9000 | F12: =IF(Таблица323[[#This Row],[Цена ]]>0,Таблица323[[#This Row],[Цена ]]*Таблица323[[#This Row],[Заказ]],"") -> 0
A13: 281312-3BU | B13: Samsung Galaxy A26 5G 6+128GB Peach Pink RUS Уценка | C13: Коробка пробита с тыльной стороны, пломбы целые | D13: 13200 | F13: =IF(Таблица323[[#This Row],[Цена ]]>0,Таблица323[[#This Row],[Цена ]]*Таблица323[[#This Row],[Заказ]],"") -> 0
A14: 281313-4BU | B14: Samsung Galaxy A26 5G 8+256GB White RUS Уценка | C14: Коробка пробита с тыльной стороны, пломбы целые | D14: 16500 | F14: =IF(Таблица323[[#This Row],[Цена ]]>0,Таблица323[[#This Row],[Цена ]]*Таблица323[[#This Row],[Заказ]],"") -> 0
A15: Итог | E15: =SUBTOTAL(109,Таблица323[Заказ]) -> 0 | F15: =SUBTOTAL(109,Таблица323[Сумма заказа]) -> 0

Sheet Аксессуары и гаджеты в наличии
A1: Назад в оглавление
A2: Аксессуары и гаджеты в наличии (безнал с НДС 22% и наличные)
A3: Срок поставки с нашего склада 1-2 день. Предоплата 100%
E4: итого | F4: =SUM(Таблица62541616[Заказ наличные]) -> 0 | G4: =SUM(Таблица62541616[заказ б/н]) -> 0 | H4: =SUM(Таблица62541616[сумма заказа наличные]) -> 0 | I4: =SUM(Таблица62541616[Сумма заказа б/н]) -> 0
A5: артикул | B5: Полное название модели | C5: доступное количество | D5: цена наличные | E5: Цена б/н | F5: Заказ наличные | G5: заказ б/н | H5: сумма заказа наличные | I5: Сумма заказа б/н
A6: Аксессуары / Наушники / Беспроводные наушники / Redmi | H6: =IF(Таблица62541616[[#This Row],[цена наличные]]<>"",Таблица62541616[[#This Row],[цена наличные]]*Таблица62541616[[#This Row],[Заказ наличные]],"") | I6: =IF(Таблица62541616[[#This Row],[цена наличные]]<>"",Таблица62541616[[#This Row],[Цена б/н]]*Таблица62541616[[#This Row],[заказ б/н]],"")
A7: 994057-3RUS | B7: Беспроводные наушники REDMI Buds 8 Pro (BHR08GJGL) Cloud White RUS | C7: 7 | D7: 4500 | E7: 5350 | H7: =IF(Таблица62541616[[#This Row],[цена наличные]]<>"",Таблица62541616[[#This Row],[цена наличные]]*Таблица62541616[[#This Row],[Заказ наличные]],"") -> 0 | I7: =IF(Таблица62541616[[#This Row],[цена наличные]]<>"",Таблица62541616[[#This Row],[Цена б/н]]*Таблица62541616[[#This Row],[заказ б/н]],"") -> 0
A8: 994057-1RUS | B8: Беспроводные наушники REDMI Buds 8 Pro (BHR08GMGL) Glacier Blue RUS | C8: 13 | D8: 4500 | E8: 5350 | H8: =IF(Таблица62541616[[#This Row],[цена наличные]]<>"",Таблица62541616[[#This Row],[цена наличные]]*Таблица62541616[[#This Row],[Заказ наличные]],"") -> 0 | I8: =IF(Таблица62541616[[#This Row],[цена наличные]]<>"",Таблица62541616[[#This Row],[Цена б/н]]*Таблица62541616[[#This Row],[заказ б/н]],"") -> 0
A9: Аксессуары / Пылесосы / Роботы-пылесосы / Mi | H9: =IF(Таблица62541616[[#This Row],[цена наличные]]<>"",Таблица62541616[[#This Row],[цена наличные]]*Таблица62541616[[#This Row],[Заказ наличные]],"") | I9: =IF(Таблица62541616[[#This Row],[цена наличные]]<>"",Таблица62541616[[#This Row],[Цена б/н]]*Таблица62541616[[#This Row],[заказ б/н]],"")
A10: 904520RUS | B10: Робот-пылесос Xiaomi Robot Vacuum H40 (BHR07XBEU) RUS | C10: 10 | D10: 17900 | E10: 21910 | H10: =IF(Таблица62541616[[#This Row],[цена наличные]]<>"",Таблица62541616[[#This Row],[цена наличные]]*Таблица62541616[[#This Row],[Заказ наличные]],"") -> 0 | I10: =IF(Таблица62541616[[#This Row],[цена наличные]]<>"",Таблица62541616[[#This Row],[Цена б/н]]*Таблица62541616[[#This Row],[заказ б/н]],"") -> 0
A11: 822374-1RUS | B11: Робот-пылесос Xiaomi Robot Vacuum S40 (BHR084AEU) White RUS | C11: 15 | D11: 12400 | E11: 14590 | H11: =IF(Таблица62541616[[#This Row],[цена наличные]]<>"",Таблица62541616[[#This Row],[цена наличные]]*Таблица62541616[[#This Row],[Заказ наличные]],"") -> 0 | I11: =IF(Таблица62541616[[#This Row],[цена наличные]]<>"",Таблица62541616[[#This Row],[Цена б/н]]*Таблица62541616[[#This Row],[заказ б/н]],"") -> 0
A12: 822377-1RUS | B12: Робот-пылесос Xiaomi Robot Vacuum S40 Pro (BHR089REU) White RUS | C12: 10 | D12: 18200 | E12: 21290 | H12: =IF(Таблица62541616[[#This Row],[цена наличные]]<>"",Таблица62541616[[#This Row],[цена наличные]]*Таблица62541616[[#This Row],[Заказ наличные]],"") -> 0 | I12: =IF(Таблица62541616[[#This Row],[цена наличные]]<>"",Таблица62541616[[#This Row],[Цена б/н]]*Таблица62541616[[#This Row],[заказ б/н]],"") -> 0
A13: 822375-1RUS | B13: Робот-пылесос Xiaomi Robot Vacuum S40C (BHR9664EU) White RUS | C13: 14 | D13: 10400 | E13: 12240 | H13: =IF(Таблица62541616[[#This Row],[цена наличные]]<>"",Таблица62541616[[#This Row],[цена наличные]]*Таблица62541616[[#This Row],[Заказ наличные]],"") -> 0 | I13: =IF(Таблица62541616[[#This Row],[цена наличные]]<>"",Таблица62541616[[#This Row],[Цена б/н]]*Таблица62541616[[#This Row],[заказ б/н]],"") -> 0
A14: Аксессуары / Часы и фитнес-браслеты / Фитнес-браслеты / Mi | H14: =IF(Таблица62541616[[#This Row],[цена наличные]]<>"",Таблица62541616[[#This Row],[цена наличные]]*Таблица62541616[[#This Row],[Заказ наличные]],"") | I14: =IF(Таблица62541616[[#This Row],[цена наличные]]<>"",Таблица62541616[[#This Row],[Цена б/н]]*Таблица62541616[[#This Row],[заказ б/н]],"")
A15: 440028-5RUS | B15: Фитнес трекер Xiaomi Smart Band 9 Active (BHR08L3GL) Purple RUS | C15: 13 | D15: 3000 | E15: 3400 | H15: =IF(Таблица62541616[[#This Row],[цена наличные]]<>"",Таблица62541616[[#This Row],[цена наличные]]*Таблица62541616[[#This Row],[Заказ наличные]],"") -> 0 | I15: =IF(Таблица62541616[[#This Row],[цена наличные]]<>"",Таблица62541616[[#This Row],[Цена б/н]]*Таблица62541616[[#This Row],[заказ б/н]],"") -> 0
A16: 440028-1RUS | B16: Фитнес трекер Xiaomi Smart Band 9 Active (BHR9441GL) Beige White RUS | C16: 10 | D16: 3000 | E16: 3400 | H16: =IF(Таблица62541616[[#This Row],[цена наличные]]<>"",Таблица62541616[[#This Row],[цена наличные]]*Таблица62541616[[#This Row],[Заказ наличные]],"") -> 0 | I16: =IF(Таблица62541616[[#This Row],[цена наличные]]<>"",Таблица62541616[[#This Row],[Цена б/н]]*Таблица62541616[[#This Row],[заказ б/н]],"") -> 0
A17: 440028-3RUS | B17: Фитнес трекер Xiaomi Smart Band 9 Active (BHR9917GL) Pink RUS | C17: 13 | D17: 4200 | E17: 4700 | H17: =IF(Таблица62541616[[#This Row],[цена наличные]]<>"",Таблица62541616[[#This Row],[цена наличные]]*Таблица62541616[[#This Row],[Заказ наличные]],"") -> 0 | I17: =IF(Таблица62541616[[#This Row],[цена наличные]]<>"",Таблица62541616[[#This Row],[Цена б/н]]*Таблица62541616[[#This Row],[заказ б/н]],"") -> 0
A18: 902059-1RUS | B18: Фитнес-браслет Xiaomi Smart Band 10 Ceramic (BHR07Y5GL) Ceramic Edition Pearl White RUS | C18: 13 | D18: 3000 | E18: 3400 | H18: =IF(Таблица62541616[[#This Row],[цена наличные]]<>"",Таблица62541616[[#This Row],[цена наличные]]*Таблица62541616[[#This Row],[Заказ наличные]],"") -> 0 | I18: =IF(Таблица62541616[[#This Row],[цена наличные]]<>"",Таблица62541616[[#This Row],[Цена б/н]]*Таблица62541616[[#This Row],[заказ б/н]],"") -> 0
A19: 900962-1RUS | B19: Фитнес-браслет Xiaomi Smart Band 10 Glacier Silver (BHR07PSGL) RUS | C19: 10 | D19: 1650 | E19: 1900 | H19: =IF(Таблица62541616[[#This Row],[цена наличные]]<>"",Таблица62541616[[#This Row],[цена наличные]]*Таблица62541616[[#This Row],[Заказ наличные]],"") -> 0 | I19: =IF(Таблица62541616[[#This Row],[цена наличные]]<>"",Таблица62541616[[#This Row],[Цена б/н]]*Таблица62541616[[#This Row],[заказ б/н]],"") -> 0
A20: 900962-2RUS | B20: Фитнес-браслет Xiaomi Smart Band 10 Midnight Black (BHR07PYGL) RUS | C20: 14 | D20: 1650 | E20: 1900 | H20: =IF(Таблица62541616[[#This Row],[цена наличные]]<>"",Таблица62541616[[#This Row],[цена наличные]]*Таблица62541616[[#This Row],[Заказ наличные]],"") -> 0 | I20: =IF(Таблица62541616[[#This Row],[цена наличные]]<>"",Таблица62541616[[#This Row],[Цена б/н]]*Таблица62541616[[#This Row],[заказ б/н]],"") -> 0
A21: 900962-3RUS | B21: Фитнес-браслет Xiaomi Smart Band 10 Mystic Rose (BHR9999GL) RUS | C21: 13 | D21: 1650 | E21: 1900 | H21: =IF(Таблица62541616[[#This Row],[цена наличные]]<>"",Таблица62541616[[#This Row],[цена наличные]]*Таблица62541616[[#This Row],[Заказ наличные]],"") -> 0 | I21: =IF(Таблица62541616[[#This Row],[цена наличные]]<>"",Таблица62541616[[#This Row],[Цена б/н]]*Таблица62541616[[#This Row],[заказ б/н]],"") -> 0
A22: 801461-1RUS | B22: Фитнес-браслет Xiaomi Smart Band 9 Pro Moonlight Silver (BHR8715GL) RUS | C22: 11 | D22: 5350 | E22: 6000 | H22: =IF(Таблица62541616[[#This Row],[цена наличные]]<>"",Таблица62541616[[#This Row],[цена наличные]]*Таблица62541616[[#This Row],[Заказ наличные]],"") -> 0 | I22: =IF(Таблица62541616[[#This Row],[цена наличные]]<>"",Таблица62541616[[#This Row],[Цена б/н]]*Таблица62541616[[#This Row],[заказ б/н]],"") -> 0
A23: 801461-2RUS | B23: Фитнес-браслет Xiaomi Smart Band 9 Pro Obsidian Black (BHR8710GL) RUS | C23: 12 | D23: 5350 | E23: 6000 | H23: =IF(Таблица62541616[[#This Row],[цена наличные]]<>"",Таблица62541616[[#This Row],[цена наличные]]*Таблица62541616[[#This Row],[Заказ наличные]],"") -> 0 | I23: =IF(Таблица62541616[[#This Row],[цена наличные]]<>"",Таблица62541616[[#This Row],[Цена б/н]]*Таблица62541616[[#This Row],[заказ б/н]],"") -> 0

Sheet Гаджеты и МБТ
A1: Назад в оглавление
A2: Аксессуары(наличные). Отгрузка со склада "Рубин" 1 рабочий день. Предолата 100% | C2: итого | D2: =SUM(Таблица7[Заказ]) -> 0 | E2: =SUM(Таблица7[Сумма заказа]) -> 0
A3: Код | B3: Наименование | C3: Цена | D3: Заказ | E3: Сумма заказа | F3: Особенности заказа | G3: Особенности заказа2
A4: Аксессуары / Аксессуары и гаджеты / Asus | E4: =IF(Таблица7[[#This Row],[Цена]]<>"",Таблица7[[#This Row],[Цена]]*Таблица7[[#This Row],[Заказ]],"") | F4: =IF(OR(ISBLANK(C4),(I4)>0),"","предзаказ в течение 1-3 рабочих дней") | G4: =IF(IFERROR(VLOOKUP(Таблица7[[#This Row],[Наименование]],#REF!,2,0),-1)>0,1001,IF(IFERROR(VLOOKUP(Таблица7[[#This Row],[Наименование]],#REF!,2,0),-1)>0,50,IF(IFERROR(VLOOKUP(Таблица7[[#This Row],[Наименование]],#REF!,2,0),-1)>0,1002,IF(IFERROR(VLOOKUP(Таблица7[[#This Row],[Наименование]],#REF!,2,0),-1)>0,1003,)))) -> 0
A5: 996018RUS | B5: Роутер ASUS (RT-AX1800U) Wi-Fi 6, USB Type-A RUS | C5: 4300 | E5: =IF(Таблица7[[#This Row],[Цена]]<>"",Таблица7[[#This Row],[Цена]]*Таблица7[[#This Row],[Заказ]],"") -> 0 | F5: =IF(OR(ISBLANK(C5),(I5)>0),"","предзаказ в течение 1-3 рабочих дней") -> предзаказ в течение 1-3 рабочих дней | G5: =IF(IFERROR(VLOOKUP(Таблица7[[#This Row],[Наименование]],#REF!,2,0),-1)>0,1001,IF(IFERROR(VLOOKUP(Таблица7[[#This Row],[Наименование]],#REF!,2,0),-1)>0,50,IF(IFERROR(VLOOKUP(Таблица7[[#This Row],[Наименование]],#REF!,2,0),-1)>0,1002,IF(IFERROR(VLOOKUP(Таблица7[[#This Row],[Наименование]],#REF!,2,0),-1)>0,1003,)))) -> 0
A6: Аксессуары / Аксессуары и гаджеты / Cudy | E6: =IF(Таблица7[[#This Row],[Цена]]<>"",Таблица7[[#This Row],[Цена]]*Таблица7[[#This Row],[Заказ]],"") | F6: =IF(OR(ISBLANK(C6),(I6)>0),"","предзаказ в течение 1-3 рабочих дней") | G6: =IF(IFERROR(VLOOKUP(Таблица7[[#This Row],[Наименование]],#REF!,2,0),-1)>0,1001,IF(IFERROR(VLOOKUP(Таблица7[[#This Row],[Наименование]],#REF!,2,0),-1)>0,50,IF(IFERROR(VLOOKUP(Таблица7[[#This Row],[Наименование]],#REF!,2,0),-1)>0,1002,IF(IFERROR(VLOOKUP(Таблица7[[#This Row],[Наименование]],#REF!,2,0),-1)>0,1003,)))) -> 0
A7: 801221RUS | B7: Коммутатор Cudy GS1006P неуправляемый 6 портов 1Гбит/с 4xPoE 65W (GS1006P) RUS | C7: 3400 | E7: =IF(Таблица7[[#This Row],[Цена]]<>"",Таблица7[[#This Row],[Цена]]*Таблица7[[#This Row],[Заказ]],"") -> 0 | F7: =IF(OR(ISBLANK(C7),(I7)>0),"","предзаказ в течение 1-3 рабочих дней") -> предзаказ в течение 1-3 рабочих дней | G7: =IF(IFERROR(VLOOKUP(Таблица7[[#This Row],[Наименование]],#REF!,2,0),-1)>0,1001,IF(IFERROR(VLOOKUP(Таблица7[[#This Row],[Наименование]],#REF!,2,0),-1)>0,50,IF(IFERROR(VLOOKUP(Таблица7[[#This Row],[Наименование]],#REF!,2,0),-1)>0,1002,IF(IFERROR(VLOOKUP(Таблица7[[#This Row],[Наименование]],#REF!,2,0),-1)>0,1003,)))) -> 0
A8: 801226RUS | B8: Сетевой адаптер Cudy WU1300S Wi-Fi5 AC1300 USB 3.0 (WU1300S) RUS | C8: 1000 | E8: =IF(Таблица7[[#This Row],[Цена]]<>"",Таблица7[[#This Row],[Цена]]*Таблица7[[#This Row],[Заказ]],"") -> 0 | F8: =IF(OR(ISBLANK(C8),(I8)>0),"","предзаказ в течение 1-3 рабочих дней") -> предзаказ в течение 1-3 рабочих дней | G8: =IF(IFERROR(VLOOKUP(Таблица7[[#This Row],[Наименование]],#REF!,2,0),-1)>0,1001,IF(IFERROR(VLOOKUP(Таблица7[[#This Row],[Наименование]],#REF!,2,0),-1)>0,50,IF(IFERROR(VLOOKUP(Таблица7[[#This Row],[Наименование]],#REF!,2,0),-1)>0,1002,IF(IFERROR(VLOOKUP(Таблица7[[#This Row],[Наименование]],#REF!,2,0),-1)>0,1003,)))) -> 0
A9: Аксессуары / Аксессуары и гаджеты / Dyson | E9: =IF(Таблица7[[#This Row],[Цена]]<>"",Таблица7[[#This Row],[Цена]]*Таблица7[[#This Row],[Заказ]],"") | F9: =IF(OR(ISBLANK(C9),(I9)>0),"","предзаказ в течение 1-3 рабочих дней") | G9: =IF(IFERROR(VLOOKUP(Таблица7[[#This Row],[Наименование]],#REF!,2,0),-1)>0,1001,IF(IFERROR(VLOOKUP(Таблица7[[#This Row],[Наименование]],#REF!,2,0),-1)>0,50,IF(IFERROR(VLOOKUP(Таблица7[[#This Row],[Наименование]],#REF!,2,0),-1)>0,1002,IF(IFERROR(VLOOKUP(Таблица7[[#This Row],[Наименование]],#REF!,2,0),-1)>0,1003,)))) -> 0
A10: 810321-1 | B10: Беспроводные наушники Dyson OnTrac Ceramic Cinnabar | C10: 20500 | E10: =IF(Таблица7[[#This Row],[Цена]]<>"",Таблица7[[#This Row],[Цена]]*Таблица7[[#This Row],[Заказ]],"") -> 0 | F10: =IF(OR(ISBLANK(C10),(I10)>0),"","предзаказ в течение 1-3 рабочих дней") -> предзаказ в течение 1-3 рабочих дней | G10: =IF(IFERROR(VLOOKUP(Таблица7[[#This Row],[Наименование]],#REF!,2,0),-1)>0,1001,IF(IFERROR(VLOOKUP(Таблица7[[#This Row],[Наименование]],#REF!,2,0),-1)>0,50,IF(IFERROR(VLOOKUP(Таблица7[[#This Row],[Наименование]],#REF!,2,0),-1)>0,1002,IF(IFERROR(VLOOKUP(Таблица7[[#This Row],[Наименование]],#REF!,2,0),-1)>0,1003,)))) -> 0
A11: Аксессуары / Аксессуары и гаджеты / Fujifilm | E11: =IF(Таблица7[[#This Row],[Цена]]<>"",Таблица7[[#This Row],[Цена]]*Таблица7[[#This Row],[Заказ]],"") | F11: =IF(OR(ISBLANK(C11),(I11)>0),"","предзаказ в течение 1-3 рабочих дней") | G11: =IF(IFERROR(VLOOKUP(Таблица7[[#This Row],[Наименование]],#REF!,2,0),-1)>0,1001,IF(IFERROR(VLOOKUP(Таблица7[[#This Row],[Наименование]],#REF!,2,0),-1)>0,50,IF(IFERROR(VLOOKUP(Таблица7[[#This Row],[Наименование]],#REF!,2,0),-1)>0,1002,IF(IFERROR(VLOOKUP(Таблица7[[#This Row],[Наименование]],#REF!,2,0),-1)>0,1003,)))) -> 0
A12: 812994-1 | B12: Фотоаппарат Моментальной Печати Fujifilm Instax Mini Evo Black | C12: 15400 | E12: =IF(Таблица7[[#This Row],[Цена]]<>"",Таблица7[[#This Row],[Цена]]*Таблица7[[#This Row],[Заказ]],"") -> 0 | F12: =IF(OR(ISBLANK(C12),(I12)>0),"","предзаказ в течение 1-3 рабочих дней") -> предзаказ в течение 1-3 рабочих дней | G12: =IF(IFERROR(VLOOKUP(Таблица7[[#This Row],[Наименование]],#REF!,2,0),-1)>0,1001,IF(IFERROR(VLOOKUP(Таблица7[[#This Row],[Наименование]],#REF!,2,0),-1)>0,50,IF(IFERROR(VLOOKUP(Таблица7[[#This Row],[Наименование]],#REF!,2,0),-1)>0,1002,IF(IFERROR(VLOOKUP(Таблица7[[#This Row],[Наименование]],#REF!,2,0),-1)>0,1003,)))) -> 0
A13: 812994-2 | B13: Фотоаппарат Моментальной Печати Fujifilm Instax Mini Evo Brown | C13: 15400 | E13: =IF(Таблица7[[#This Row],[Цена]]<>"",Таблица7[[#This Row],[Цена]]*Таблица7[[#This Row],[Заказ]],"") -> 0 | F13: =IF(OR(ISBLANK(C13),(I13)>0),"","предзаказ в течение 1-3 рабочих дней") -> предзаказ в течение 1-3 рабочих дней | G13: =IF(IFERROR(VLOOKUP(Таблица7[[#This Row],[Наименование]],#REF!,2,0),-1)>0,1001,IF(IFERROR(VLOOKUP(Таблица7[[#This Row],[Наименование]],#REF!,2,0),-1)>0,50,IF(IFERROR(VLOOKUP(Таблица7[[#This Row],[Наименование]],#REF!,2,0),-1)>0,1002,IF(IFERROR(VLOOKUP(Таблица7[[#This Row],[Наименование]],#REF!,2,0),-1)>0,1003,)))) -> 0
A14: 812996-1 | B14: Фотоаппарат Моментальной Печати Fujifilm Instax Mini Evo Cinema Black | C14: 29400 | E14: =IF(Таблица7[[#This Row],[Цена]]<>"",Таблица7[[#This Row],[Цена]]*Таблица7[[#This Row],[Заказ]],"") -> 0 | F14: =IF(OR(ISBLANK(C14),(I14)>0),"","предзаказ в течение 1-3 рабочих дней") -> предзаказ в течение 1-3 рабочих дней | G14: =IF(IFERROR(VLOOKUP(Таблица7[[#This Row],[Наименование]],#REF!,2,0),-1)>0,1001,IF(IFERROR(VLOOKUP(Таблица7[[#This Row],[Наименование]],#REF!,2,0),-1)>0,50,IF(IFERROR(VLOOKUP(Таблица7[[#This Row],[Наименование]],#REF!,2,0),-1)>0,1002,IF(IFERROR(VLOOKUP(Таблица7[[#This Row],[Наименование]],#REF!,2,0),-1)>0,1003,)))) -> 0
A15: 812995-1 | B15: Фотоаппарат Моментальной Печати Fujifilm Instax Wide Evo Black | C15: 28100 | E15: =IF(Таблица7[[#This Row],[Цена]]<>"",Таблица7[[#This Row],[Цена]]*Таблица7[[#This Row],[Заказ]],"") -> 0 | F15: =IF(OR(ISBLANK(C15),(I15)>0),"","предзаказ в течение 1-3 рабочих дней") -> предзаказ в течение 1-3 рабочих дней | G15: =IF(IFERROR(VLOOKUP(Таблица7[[#This Row],[Наименование]],#REF!,2,0),-1)>0,1001,IF(IFERROR(VLOOKUP(Таблица7[[#This Row],[Наименование]],#REF!,2,0),-1)>0,50,IF(IFERROR(VLOOKUP(Таблица7[[#This Row],[Наименование]],#REF!,2,0),-1)>0,1002,IF(IFERROR(VLOOKUP(Таблица7[[#This Row],[Наименование]],#REF!,2,0),-1)>0,1003,)))) -> 0
A16: Аксессуары / Аксессуары и гаджеты / GoPro / Камеры GoPro HERO | E16: =IF(Таблица7[[#This Row],[Цена]]<>"",Таблица7[[#This Row],[Цена]]*Таблица7[[#This Row],[Заказ]],"") | F16: =IF(OR(ISBLANK(C16),(I16)>0),"","предзаказ в течение 1-3 рабочих дней") | G16: =IF(IFERROR(VLOOKUP(Таблица7[[#This Row],[Наименование]],#REF!,2,0),-1)>0,1001,IF(IFERROR(VLOOKUP(Таблица7[[#This Row],[Наименование]],#REF!,2,0),-1)>0,50,IF(IFERROR(VLOOKUP(Таблица7[[#This Row],[Наименование]],#REF!,2,0),-1)>0,1002,IF(IFERROR(VLOOKUP(Таблица7[[#This Row],[Наименование]],#REF!,2,0),-1)>0,1003,)))) -> 0
A17: 84123-1EU | B17: Камера GoPro Hero 13 Accessory Bundle 64GB Black EU | C17: 30900 | E17: =IF(Таблица7[[#This Row],[Цена]]<>"",Таблица7[[#This Row],[Цена]]*Таблица7[[#This Row],[Заказ]],"") -> 0 | F17: =IF(OR(ISBLANK(C17),(I17)>0),"","предзаказ в течение 1-3 рабочих дней") -> предзаказ в течение 1-3 рабочих дней | G17: =IF(IFERROR(VLOOKUP(Таблица7[[#This Row],[Наименование]],#REF!,2,0),-1)>0,1001,IF(IFERROR(VLOOKUP(Таблица7[[#This Row],[Наименование]],#REF!,2,0),-1)>0,50,IF(IFERROR(VLOOKUP(Таблица7[[#This Row],[Наименование]],#REF!,2,0),-1)>0,1002,IF(IFERROR(VLOOKUP(Таблица7[[#This Row],[Наименование]],#REF!,2,0),-1)>0,1003,)))) -> 0
A18: 84121-1EU | B18: Камера GoPro Hero 13 Black EU | C18: 23100 | E18: =IF(Таблица7[[#This Row],[Цена]]<>"",Таблица7[[#This Row],[Цена]]*Таблица7[[#This Row],[Заказ]],"") -> 0 | F18: =IF(OR(ISBLANK(C18),(I18)>0),"","предзаказ в течение 1-3 рабочих дней") -> предзаказ в течение 1-3 рабочих дней | G18: =IF(IFERROR(VLOOKUP(Таблица7[[#This Row],[Наименование]],#REF!,2,0),-1)>0,1001,IF(IFERROR(VLOOKUP(Таблица7[[#This Row],[Наименование]],#REF!,2,0),-1)>0,50,IF(IFERROR(VLOOKUP(Таблица7[[#This Row],[Наименование]],#REF!,2,0),-1)>0,1002,IF(IFERROR(VLOOKUP(Таблица7[[#This Row],[Наименование]],#REF!,2,0),-1)>0,1003,)))) -> 0
A19: Аксессуары / Аксессуары и гаджеты / Harman Kardon | E19: =IF(Таблица7[[#This Row],[Цена]]<>"",Таблица7[[#This Row],[Цена]]*Таблица7[[#This Row],[Заказ]],"") | F19: =IF(OR(ISBLANK(C19),(I19)>0),"","предзаказ в течение 1-3 рабочих дней") | G19: =IF(IFERROR(VLOOKUP(Таблица7[[#This Row],[Наименование]],#REF!,2,0),-1)>0,1001,IF(IFERROR(VLOOKUP(Таблица7[[#This Row],[Наименование]],#REF!,2,0),-1)>0,50,IF(IFERROR(VLOOKUP(Таблица7[[#This Row],[Наименование]],#REF!,2,0),-1)>0,1002,IF(IFERROR(VLOOKUP(Таблица7[[#This Row],[Наименование]],#REF!,2,0),-1)>0,1003,)))) -> 0
A20: 50308-1 | B20: Беспроводная колонка Harman Kardon Onyx Studio 9 Black | C20: 17000 | E20: =IF(Таблица7[[#This Row],[Цена]]<>"",Таблица7[[#This Row],[Цена]]*Таблица7[[#This Row],[Заказ]],"") -> 0 | F20: =IF(OR(ISBLANK(C20),(I20)>0),"","предзаказ в течение 1-3 рабочих дней") -> предзаказ в течение 1-3 рабочих дней | G20: =IF(IFERROR(VLOOKUP(Таблица7[[#This Row],[Наименование]],#REF!,2,0),-1)>0,1001,IF(IFERROR(VLOOKUP(Таблица7[[#This Row],[Наименование]],#REF!,2,0),-1)>0,50,IF(IFERROR(VLOOKUP(Таблица7[[#This Row],[Наименование]],#REF!,2,0),-1)>0,1002,IF(IFERROR(VLOOKUP(Таблица7[[#This Row],[Наименование]],#REF!,2,0),-1)>0,1003,)))) -> 0
A21: 50308-2 | B21: Беспроводная колонка Harman Kardon Onyx Studio 9 Grey | C21: 17000 | E21: =IF(Таблица7[[#This Row],[Цена]]<>"",Таблица7[[#This Row],[Цена]]*Таблица7[[#This Row],[Заказ]],"") -> 0 | F21: =IF(OR(ISBLANK(C21),(I21)>0),"","предзаказ в течение 1-3 рабочих дней") -> предзаказ в течение 1-3 рабочих дней | G21: =IF(IFERROR(VLOOKUP(Таблица7[[#This Row],[Наименование]],#REF!,2,0),-1)>0,1001,IF(IFERROR(VLOOKUP(Таблица7[[#This Row],[Наименование]],#REF!,2,0),-1)>0,50,IF(IFERROR(VLOOKUP(Таблица7[[#This Row],[Наименование]],#REF!,2,0),-1)>0,1002,IF(IFERROR(VLOOKUP(Таблица7[[#This Row],[Наименование]],#REF!,2,0),-1)>0,1003,)))) -> 0
